<?xml version="1.0" ?>
<!-- =================================================================================== -->
<!-- |    This document was autogenerated by xacro from kv01_klb4off.xacro             | -->
<!-- |    EDITING THIS FILE BY HAND IS NOT RECOMMENDED                                 | -->
<!-- =================================================================================== -->
<!--> 
Vytvorenie base framu a celej zakladne
</!-->
<robot name="kv01" xmlns:controller="http://playerstage.sourceforge.net/gazebo/xmlschema/#controller" xmlns:interface="http://playerstage.sourceforge.net/gazebo/xmlschema/#interface" xmlns:sensor="http://playerstage.sourceforge.net/gazebo/xmlschema/#sensor" xmlns:xacro="http://www.ros.org/wiki/xacro">
  <package>
    <depend package="collada_urdf"/>
  </package>
  <material name="Black">
    <color rgba="0.0 0.0 0.0 1.0"/>
  </material>
  <material name="Blue">
    <color rgba="0.0 0.0 0.8 1.0"/>
  </material>
  <material name="Green">
    <color rgba="0.0 0.8 0.0 1.0"/>
  </material>
  <material name="Grey">
    <color rgba="0.2 0.2 0.2 1.0"/>
  </material>
  <material name="White">
    <color rgba="1.0 1.0 1.0 1.0"/>
  </material>
  <gazebo>
    <plugin filename="libgazebo_ros_control.so" name="gazebo_ros_control">
      <robotNamespace>/kv01</robotNamespace>
    </plugin>
  </gazebo>
  <gazebo reference="frame_to_world">
    <mu1>0.5</mu1>
    <mu2>0.5</mu2>
    <turnGravityOff>false</turnGravityOff>
    <material>Gazebo/Black</material>
  </gazebo>
  <gazebo reference="base_link">
    <mu1>0.5</mu1>
    <mu2>0.5</mu2>
    <turnGravityOff>false</turnGravityOff>
    <material>Gazebo/Blue</material>
  </gazebo>
  <gazebo reference="scan">
    <mu1>0.5</mu1>
    <mu2>0.5</mu2>
    <turnGravityOff>false</turnGravityOff>
    <material>Gazebo/Black</material>
  </gazebo>
  <gazebo reference="camera_l">
    <mu1>0.5</mu1>
    <mu2>0.5</mu2>
    <turnGravityOff>false</turnGravityOff>
    <material>Gazebo/Black</material>
  </gazebo>
  <gazebo reference="camera_r">
    <mu1>0.5</mu1>
    <mu2>0.5</mu2>
    <turnGravityOff>false</turnGravityOff>
    <material>Gazebo/Black</material>
  </gazebo>
  <gazebo reference="camera">
    <mu1>0.5</mu1>
    <mu2>0.5</mu2>
    <turnGravityOff>false</turnGravityOff>
    <material>Gazebo/Black</material>
  </gazebo>
  <gazebo reference="veza">
    <mu1>0.5</mu1>
    <mu2>0.5</mu2>
    <turnGravityOff>false</turnGravityOff>
    <material>Gazebo/White</material>
  </gazebo>
  <gazebo reference="wheel_lp">
    <mu1>0.5</mu1>
    <mu2>0.5</mu2>
    <turnGravityOff>false</turnGravityOff>
    <material>Gazebo/Black</material>
  </gazebo>
  <gazebo reference="wheel_lz">
    <mu1>0.5</mu1>
    <mu2>0.5</mu2>
    <turnGravityOff>false</turnGravityOff>
    <material>Gazebo/Black</material>
  </gazebo>
  <gazebo reference="wheel_pp">
    <mu1>0.5</mu1>
    <mu2>0.5</mu2>
    <turnGravityOff>false</turnGravityOff>
    <material>Gazebo/Black</material>
  </gazebo>
  <gazebo reference="wheel_pz">
    <mu1>0.5</mu1>
    <mu2>0.5</mu2>
    <turnGravityOff>false</turnGravityOff>
    <material>Gazebo/Black</material>
  </gazebo>
  <!--> Gadzebo definicia ramena</!-->
  <gazebo reference="model_klb0">
    <mu1>0.5</mu1>
    <mu2>0.5</mu2>
    <turnGravityOff>false</turnGravityOff>
    <material>Gazebo/Blue</material>
  </gazebo>
  <gazebo reference="model_klb1">
    <mu1>0.5</mu1>
    <mu2>0.5</mu2>
    <turnGravityOff>false</turnGravityOff>
    <material>Gazebo/White</material>
  </gazebo>
  <gazebo reference="link_1_2">
    <mu1>0.5</mu1>
    <mu2>0.5</mu2>
    <turnGravityOff>false</turnGravityOff>
    <material>Gazebo/White</material>
  </gazebo>
  <gazebo reference="menic1_2">
    <mu1>0.5</mu1>
    <mu2>0.5</mu2>
    <turnGravityOff>false</turnGravityOff>
    <material>Gazebo/Blue</material>
  </gazebo>
  <gazebo reference="model_klb2">
    <mu1>0.5</mu1>
    <mu2>0.5</mu2>
    <turnGravityOff>false</turnGravityOff>
    <material>Gazebo/Blue</material>
  </gazebo>
  <gazebo reference="link_2_3">
    <mu1>0.5</mu1>
    <mu2>0.5</mu2>
    <turnGravityOff>false</turnGravityOff>
    <material>Gazebo/Blue</material>
  </gazebo>
  <gazebo reference="model_klb3">
    <mu1>0.5</mu1>
    <mu2>0.5</mu2>
    <turnGravityOff>false</turnGravityOff>
    <material>Gazebo/Blue</material>
  </gazebo>
  <gazebo reference="link_3_4">
    <mu1>0.5</mu1>
    <mu2>0.5</mu2>
    <turnGravityOff>false</turnGravityOff>
    <material>Gazebo/White</material>
  </gazebo>
  <gazebo reference="link_3_4x">
    <mu1>0.5</mu1>
    <mu2>0.5</mu2>
    <turnGravityOff>false</turnGravityOff>
    <material>Gazebo/Blue</material>
  </gazebo>
  <gazebo reference="model_klb4">
    <mu1>0.5</mu1>
    <mu2>0.5</mu2>
    <turnGravityOff>false</turnGravityOff>
    <material>Gazebo/Blue</material>
  </gazebo>
  <gazebo reference="menic4_5">
    <mu1>0.5</mu1>
    <mu2>0.5</mu2>
    <turnGravityOff>false</turnGravityOff>
    <material>Gazebo/Blue</material>
  </gazebo>
  <gadzebo reference="camera_r_to_camera">
    <erp>0.1</erp>
    <stopKd value="1000000.0"/>
    <stopKp value="10000.0"/>
    <fudgeFactor value="0.3"/>
    <implicitSpringDamper>true</implicitSpringDamper>
  </gadzebo>
  <gadzebo reference="scan_to_veza">
    <erp>0.1</erp>
    <stopKd value="1000000.0"/>
    <stopKp value="10000.0"/>
    <fudgeFactor value="0.3"/>
    <implicitSpringDamper>true</implicitSpringDamper>
  </gadzebo>
  <gadzebo reference="klb0">
    <erp>0.1</erp>
    <stopKd value="1000000.0"/>
    <stopKp value="10000.0"/>
    <fudgeFactor value="0.3"/>
    <implicitSpringDamper>true</implicitSpringDamper>
  </gadzebo>
  <gadzebo reference="klb1">
    <erp>0.1</erp>
    <stopKd value="1000000.0"/>
    <stopKp value="10000.0"/>
    <fudgeFactor value="0.3"/>
    <implicitSpringDamper>true</implicitSpringDamper>
  </gadzebo>
  <gadzebo reference="klb2">
    <erp>0.1</erp>
    <stopKd value="1000000.0"/>
    <stopKp value="10000.0"/>
    <fudgeFactor value="0.3"/>
    <implicitSpringDamper>true</implicitSpringDamper>
  </gadzebo>
  <gadzebo reference="klb3">
    <erp>0.1</erp>
    <stopKd value="1000000.0"/>
    <stopKp value="10000.0"/>
    <fudgeFactor value="0.3"/>
    <implicitSpringDamper>true</implicitSpringDamper>
  </gadzebo>
  <gadzebo reference="klb4">
    <erp>0.1</erp>
    <stopKd value="1000000.0"/>
    <stopKp value="10000.0"/>
    <fudgeFactor value="0.3"/>
    <implicitSpringDamper>true</implicitSpringDamper>
  </gadzebo>
  <gadzebo reference="klb5">
    <erp>0.1</erp>
    <stopKd value="1000000.0"/>
    <stopKp value="10000.0"/>
    <fudgeFactor value="0.3"/>
    <implicitSpringDamper>true</implicitSpringDamper>
  </gadzebo>
  <group name="right_arm">
    <chain base_link="base_link" tip_link="model_klb5"/>
  </group>
  <link name="frame_to_world"/>
  <joint name="world_to_base" type="fixed">
    <parent link="frame_to_world"/>
    <child link="base_link"/>
  </joint>
  <link name="base_link">
    <visual>
      <geometry>
        <box size="0.5 .31 .16"/>
      </geometry>
      <origin xyz="0 0 0"/>
      <material name="modra">
        <color rgba="0 0 0.8 1"/>
      </material>
    </visual>
    <inertial>
      <mass value="10"/>
      <inertia ixx="0.1" ixy="0.0" ixz="0.0" iyy="0.1" iyz="0.0" izz="0.1"/>
    </inertial>
    <collision>
      <geometry>
        <box size="0.5 .31 .30"/>
      </geometry>
      <origin xyz="0 0 0.08"/>
    </collision>
  </link>
  <link name="scan">
    <visual>
      <geometry>
        <cylinder length="0.03" radius="0.025"/>
      </geometry>
      <material name="cierna">
        <color rgba="0 0 0 1"/>
      </material>
    </visual>
    <inertial>
      <mass value="0.1"/>
      <inertia ixx="0.1" ixy="0.0" ixz="0.0" iyy="0.1" iyz="0.0" izz="0.1"/>
    </inertial>
  </link>
  <joint name="base_to_scan" type="fixed">
    <parent link="base_link"/>
    <child link="scan"/>
    <origin xyz="0.2075 0 0.095"/>
  </joint>
  <link name="veza">
    <visual>
      <geometry>
        <cylinder length="0.035" radius="0.065"/>
      </geometry>
      <material name="biela">
        <color rgba="1 1 1 1"/>
      </material>
    </visual>
    <inertial>
      <mass value="0.3"/>
      <inertia ixx="0.1" ixy="0.0" ixz="0.0" iyy="0.1" iyz="0.0" izz="0.1"/>
    </inertial>
  </link>
  <joint name="scan_to_veza" type="revolute">
    <parent link="scan"/>
    <child link="veza"/>
    <origin xyz="-0.03 0 0.0375"/>
    <axis xyz="0 0 1"/>
    <limit effort="30.0" lower="-2.09439" upper="3.14159" velocity="0.5"/>
  </joint>
  <link name="camera_l">
    <visual>
      <geometry>
        <box size="0.07 .03 .08"/>
      </geometry>
      <material name="cierna"/>
    </visual>
    <inertial>
      <mass value="0.1"/>
      <inertia ixx="0.1" ixy="0.0" ixz="0.0" iyy="0.1" iyz="0.0" izz="0.1"/>
    </inertial>
  </link>
  <joint name="veza_to_camera_l" type="fixed">
    <parent link="veza"/>
    <child link="camera_l"/>
    <origin xyz="0 0.05 0.0575"/>
  </joint>
  <link name="camera_r">
    <visual>
      <geometry>
        <box size="0.07 .03 .08"/>
      </geometry>
      <material name="cierna"/>
    </visual>
    <inertial>
      <mass value="0.1"/>
      <inertia ixx="0.1" ixy="0.0" ixz="0.0" iyy="0.1" iyz="0.0" izz="0.1"/>
    </inertial>
  </link>
  <joint name="veza_to_camera_r" type="fixed">
    <parent link="veza"/>
    <child link="camera_r"/>
    <origin xyz="0 -0.05 0.0575"/>
  </joint>
  <link name="camera">
    <visual>
      <geometry>
        <box size="0.075 .06 .06"/>
      </geometry>
      <material name="cierna"/>
    </visual>
    <inertial>
      <mass value="0.4"/>
      <inertia ixx="0.1" ixy="0.0" ixz="0.0" iyy="0.1" iyz="0.0" izz="0.1"/>
    </inertial>
  </link>
  <joint name="camera_r_to_camera" type="revolute">
    <limit effort="30.0" lower="-0.523598" upper="1.570795" velocity="0.5"/>
    <parent link="camera_r"/>
    <child link="camera"/>
    <origin rpy=" 1.570795 0 0" xyz="0 0.05 0.01"/>
    <axis xyz="0 0 1"/>
  </joint>
  <link name="wheel_frame_l">
    <visual>
      <geometry>
        <box size="0.4 .025 .1"/>
      </geometry>
      <material name="biela"/>
    </visual>
    <inertial>
      <mass value="1.3"/>
      <inertia ixx="0.1" ixy="0.0" ixz="0.0" iyy="0.1" iyz="0.0" izz="0.1"/>
    </inertial>
  </link>
  <joint name="base_link_to_wheel_frame_l" type="fixed">
    <parent link="base_link"/>
    <child link="wheel_frame_l"/>
    <origin xyz="0 +0.1775 -0.05"/>
    <axis xyz="0 1 0"/>
  </joint>
  <link name="wheel_frame_r">
    <visual>
      <geometry>
        <box size="0.4 .025 .1"/>
      </geometry>
      <material name="biela"/>
    </visual>
    <inertial>
      <mass value="1.3"/>
      <inertia ixx="0.1" ixy="0.0" ixz="0.0" iyy="0.1" iyz="0.0" izz="0.1"/>
    </inertial>
  </link>
  <joint name="base_link_to_wheel_frame_r" type="fixed">
    <parent link="base_link"/>
    <child link="wheel_frame_r"/>
    <origin xyz="0 -0.1775 -0.05"/>
    <axis xyz="0 1 0"/>
  </joint>
  <link name="wheel_lp">
    <visual>
      <geometry>
        <cylinder length="0.065" radius="0.11"/>
      </geometry>
      <material name="cierna"/>
    </visual>
    <inertial>
      <mass value="0.5"/>
      <inertia ixx="0.1" ixy="0.0" ixz="0.0" iyy="0.1" iyz="0.0" izz="0.1"/>
    </inertial>
    <collision>
      <geometry>
        <cylinder length="0.065" radius="0.11"/>
      </geometry>
    </collision>
  </link>
  <joint name="wheel_frame_l_to_wheel_lp" type="fixed">
    <parent link="wheel_frame_l"/>
    <child link="wheel_lp"/>
    <origin rpy=" 1.570795 0 0" xyz="0.145 0.05 -0.01"/>
    <axis xyz="0 0 1"/>
  </joint>
  <link name="wheel_lz">
    <visual>
      <geometry>
        <cylinder length="0.065" radius="0.11"/>
      </geometry>
      <material name="cierna"/>
    </visual>
    <inertial>
      <mass value="0.5"/>
      <inertia ixx="0.1" ixy="0.0" ixz="0.0" iyy="0.1" iyz="0.0" izz="0.1"/>
    </inertial>
    <collision>
      <geometry>
        <cylinder length="0.065" radius="0.11"/>
      </geometry>
    </collision>
  </link>
  <joint name="wheel_frame_l_to_wheel_lz" type="fixed">
    <parent link="wheel_frame_l"/>
    <child link="wheel_lz"/>
    <origin rpy=" 1.570795 0 0" xyz="-0.145 0.05 -0.01"/>
    <axis xyz="0 0 1"/>
  </joint>
  <link name="wheel_pp">
    <visual>
      <geometry>
        <cylinder length="0.065" radius="0.11"/>
      </geometry>
      <material name="cierna"/>
    </visual>
    <inertial>
      <mass value="0.5"/>
      <inertia ixx="0.1" ixy="0.0" ixz="0.0" iyy="0.1" iyz="0.0" izz="0.1"/>
    </inertial>
    <collision>
      <geometry>
        <cylinder length="0.065" radius="0.11"/>
      </geometry>
    </collision>
  </link>
  <joint name="wheel_frame_r_to_wheel_pp" type="fixed">
    <parent link="wheel_frame_r"/>
    <child link="wheel_pp"/>
    <origin rpy=" 1.570795 0 0" xyz="0.145 -0.05 -0.01"/>
    <axis xyz="0 0 1"/>
  </joint>
  <link name="wheel_pz">
    <visual>
      <geometry>
        <cylinder length="0.065" radius="0.11"/>
      </geometry>
      <material name="cierna"/>
    </visual>
    <inertial>
      <mass value="0.5"/>
      <inertia ixx="0.1" ixy="0.0" ixz="0.0" iyy="0.1" iyz="0.0" izz="0.1"/>
    </inertial>
    <collision>
      <geometry>
        <cylinder length="0.065" radius="0.11"/>
      </geometry>
    </collision>
  </link>
  <joint name="wheel_frame_r_to_wheel_pz" type="fixed">
    <parent link="wheel_frame_r"/>
    <child link="wheel_pz"/>
    <origin rpy=" 1.570795 0 0" xyz="-0.145 -0.05 -0.01"/>
    <axis xyz="0 0 1"/>
  </joint>
  <!--> 
Cast ramena pripojena k podvozku nadvazuje na base frame zakladne ... obmedzenia klbov aj linkou su predimenzovane klby su znizene pohybovo o 15 stupnov
</!-->
  <joint name="klb0" type="revolute">
    <limit effort="50" lower="-1.75" upper="1.75" velocity="0.2"/>
    <parent link="base_link"/>
    <child link="model_klb0"/>
    <origin rpy="0 0 0" xyz="0 0 .08"/>
    <axis xyz="0 0 1"/>
    <dynamics damping="1" fricction="1"/>
  </joint>
  <link name="model_klb0">
    <visual>
      <geometry>
        <cylinder length="0.258" radius="0.0725"/>
      </geometry>
      <material name="modra"/>
      <origin rpy="0 0 0" xyz="0 0 0.08"/>
    </visual>
    <inertial>
      <mass value="0.8"/>
      <inertia ixx="1" ixy="0.0" ixz="0.0" iyy="1" iyz="0.0" izz="1"/>
    </inertial>
  </link>
  <joint name="klb1" type="revolute">
    <limit effort="100" lower="-1.4" upper="1.4" velocity="0.2"/>
    <parent link="model_klb0"/>
    <child link="model_klb1"/>
    <origin rpy="0 0 0" xyz="0 0 .258"/>
    <axis xyz="0 1 0"/>
    <dynamics damping="1" fricction="1"/>
  </joint>
  <link name="model_klb1">
    <visual>
      <geometry>
        <cylinder length="0.180" radius="0.0725"/>
      </geometry>
      <material name="biela"/>
      <origin rpy="1.570795 0 0" xyz="0 0 0"/>
    </visual>
    <collision>
      <geometry>
        <cylinder length="0.180" radius="0.0725"/>
      </geometry>
      <origin rpy="1.570795 0 0" xyz="0 0 0"/>
    </collision>
    <inertial>
      <mass value="0.8"/>
      <inertia ixx="1" ixy="0.0" ixz="0.0" iyy="1" iyz="0.0" izz="1"/>
    </inertial>
  </link>
  <joint name="spoj_klb1_klb2" type="fixed">
    <parent link="model_klb1"/>
    <child link="link_1_2"/>
    <origin rpy="0 0 0" xyz="0 -0.028 0.2425"/>
  </joint>
  <link name="link_1_2">
    <visual>
      <geometry>
        <cylinder length="0.485" radius="0.040"/>
      </geometry>
      <material name="biela"/>
      <origin rpy="0 0 0" xyz="0 0 0"/>
    </visual>
    <collision>
      <geometry>
        <cylinder length="0.330" radius="0.070"/>
      </geometry>
      <origin rpy="0 0 0" xyz="0 -0.025 0.01"/>
    </collision>
    <inertial>
      <mass value="0.8"/>
      <inertia ixx="0.1" ixy="0.0" ixz="0.0" iyy="0.1" iyz="0.0" izz="0.1"/>
    </inertial>
  </link>
  <joint name="spoj_klb1_klb2_menic" type="fixed">
    <parent link="model_klb1"/>
    <child link="menic1_2"/>
    <origin rpy="0 0 0" xyz="0 -0.088 0.2425"/>
  </joint>
  <link name="menic1_2">
    <visual>
      <geometry>
        <box size="0.055 0.050 .285"/>
      </geometry>
      <material name="modra"/>
      <origin rpy="0 0 0" xyz="0 0 0.010"/>
    </visual>
    <inertial>
      <mass value="0.4"/>
      <inertia ixx="0.1" ixy="0.0" ixz="0.0" iyy="0.1" iyz="0.0" izz="0.1"/>
    </inertial>
  </link>
  <joint name="klb2" type="revolute">
    <limit effort="50" lower="-2.01" upper="2.01" velocity="0.3"/>
    <parent link="model_klb1"/>
    <child link="model_klb2"/>
    <origin rpy="0 0 0" xyz="0 0 0.485"/>
    <axis xyz="0 -1 0"/>
    <dynamics damping="1" fricction="1"/>
  </joint>
  <link name="model_klb2">
    <visual>
      <geometry>
        <cylinder length="0.190" radius="0.045"/>
      </geometry>
      <material name="modra"/>
      <origin rpy="1.570795 0 0" xyz="0 0 0"/>
    </visual>
    <collision>
      <geometry>
        <cylinder length="0.195" radius="0.050"/>
      </geometry>
      <origin rpy="1.570795 0 0" xyz="0 0 0"/>
    </collision>
    <inertial>
      <mass value="0.45"/>
      <inertia ixx="1" ixy="0.0" ixz="0.0" iyy="1" iyz="0.0" izz="1"/>
    </inertial>
  </link>
  <joint name="spoj_klb2_klb3" type="fixed">
    <parent link="model_klb2"/>
    <child link="link_2_3"/>
    <origin rpy="0 0 0" xyz="0 0.040 0"/>
  </joint>
  <link name="link_2_3">
    <visual>
      <geometry>
        <cylinder length="0.350" radius="0.045"/>
      </geometry>
      <material name="modra"/>
      <origin rpy="0 0 0" xyz="0. 0 0.175"/>
    </visual>
    <collision>
      <geometry>
        <cylinder length="0.155" radius="0.045"/>
      </geometry>
      <origin rpy="0 0 0" xyz="0.015 0 0.135"/>
    </collision>
    <inertial>
      <mass value="0.6"/>
      <inertia ixx="0.1" ixy="0.0" ixz="0.0" iyy="0.1" iyz="0.0" izz="0.1"/>
    </inertial>
  </link>
  <!-- <joint name="klb3" type="continuous">
    <limit effort="50" velocity="0.2"/>
    <parent link="model_klb2"/>
    <child link="model_klb3"/>
    <origin xyz="0 0.040 0.350 " rpy="0 0 0"/>
    <axis xyz="0 0 -1"/>
    <dynamika/>
    </joint> -->
  <joint name="klb3" type="fixed">
    <parent link="model_klb2"/>
    <child link="model_klb3"/>
    <origin rpy="0 0 0" xyz="0 0.040 0.350 "/>
    <dynamics damping="1" fricction="1"/>
  </joint>
  <link name="model_klb3">
    <visual>
      <geometry>
        <box size="0.080 .155 .035"/>
      </geometry>
      <material name="biela"/>
      <origin rpy="0 0 0" xyz="0 -0.040  -0.0175"/>
    </visual>
    <collision>
      <geometry>
        <cylinder length="0.120" radius="0.040"/>
      </geometry>
      <origin rpy=" 0 0 0" xyz="0 0 -0.055"/>
    </collision>
    <inertial>
      <mass value="0.2"/>
      <inertia ixx="1" ixy="0.0" ixz="0.0" iyy="1" iyz="0.0" izz="1"/>
    </inertial>
  </link>
  <joint name="spoj_klb4_klb5" type="fixed">
    <parent link="model_klb3"/>
    <child link="link_3_4"/>
    <origin rpy="3.14159 0 0" xyz="0 -0.076 0"/>
  </joint>
  <link name="link_3_4">
    <visual>
      <geometry>
        <cylinder length="0.2345" radius="0.027"/>
      </geometry>
      <material name="biela"/>
      <origin rpy="0 0 0" xyz="0 0 0"/>
    </visual>
    <collision>
      <geometry>
        <cylinder length="0.2335" radius="0.027"/>
      </geometry>
      <origin rpy="0 0 0" xyz="0 0 0.005"/>
    </collision>
    <inertial>
      <mass value="0.45"/>
      <inertia ixx="0.1" ixy="0.0" ixz="0.0" iyy="0.1" iyz="0.0" izz="0.1"/>
    </inertial>
  </link>
  <joint name="spoj_klb3_klb4x" type="fixed">
    <parent link="model_klb3"/>
    <child link="link_3_4x"/>
    <origin rpy="1.570795 0 0" xyz="0 -0.052 0.155"/>
  </joint>
  <link name="link_3_4x">
    <visual>
      <geometry>
        <cylinder length="0.145" radius="0.040"/>
      </geometry>
      <material name="modra"/>
      <origin rpy="0 0 0" xyz="0 0 0"/>
    </visual>
    <collision>
      <geometry>
        <cylinder length="0.145" radius="0.040"/>
      </geometry>
      <origin rpy="0 0 0" xyz="0 0 0"/>
    </collision>
    <inertial>
      <mass value="0.3"/>
      <inertia ixx="0.1" ixy="0.0" ixz="0.0" iyy="0.1" iyz="0.0" izz="0.1"/>
    </inertial>
  </link>
  <joint name="klb4" type="revolute">
    <limit effort="40" lower="-2.09" upper="2.09" velocity="0.2"/>
    <parent link="model_klb3"/>
    <child link="model_klb4"/>
    <origin rpy="0 0 0" xyz="0 0.036 0.155"/>
    <axis xyz="0 -1 0"/>
    <dynamics damping="1" fricction="1"/>
  </joint>
  <link name="model_klb4">
    <visual>
      <geometry>
        <box size="0.040 0.030 0.080"/>
      </geometry>
      <material name="modra"/>
      <origin rpy="0 0 0" xyz="0 0 0.025"/>
    </visual>
    <collision>
      <geometry>
        <box size="0.040 0.030 0.075"/>
      </geometry>
      <origin rpy="0 0 0" xyz="0 0 0.015"/>
    </collision>
    <inertial>
      <mass value="0.08"/>
      <inertia ixx="1" ixy="0.0" ixz="0.0" iyy="1" iyz="0.0" izz="1"/>
    </inertial>
  </link>
  <joint name="spoj_menic4_5_gripper" type="fixed">
    <parent link="model_klb4"/>
    <child link="menic4_5"/>
    <origin rpy="0 0 0" xyz="0 -0.015 0.055"/>
  </joint>
  <link name="menic4_5">
    <visual>
      <geometry>
        <box size="0.045 0.110 0.135"/>
      </geometry>
      <material name="modra"/>
      <origin rpy="0 0 0" xyz="0 0 0.0675"/>
    </visual>
    <collision>
      <geometry>
        <box size="0.045 0.110 0.135"/>
      </geometry>
      <origin rpy="0 0 0" xyz="0 0 0.0675"/>
    </collision>
    <inertial>
      <mass value="0.2"/>
      <inertia ixx="0.1" ixy="0.0" ixz="0.0" iyy="0.1" iyz="0.0" izz="0.1"/>
    </inertial>
  </link>
  <joint name="klb5" type="continuous">
    <limit effort="40" velocity="0.2"/>
    <parent link="model_klb4"/>
    <child link="model_klb5"/>
    <origin rpy="0 0 0" xyz="0 -0.025 0.190"/>
    <axis xyz="0 0 1"/>
    <dynamics damping="1" fricction="1"/>
  </joint>
  <link name="model_klb5">
    <visual>
      <geometry>
        <box size="0.01 0.01 0.01"/>
      </geometry>
      <origin rpy="0 0 0" xyz="0 0 0.005"/>
    </visual>
    <collision>
      <geometry>
        <box size="0.030 0.165 0.135"/>
      </geometry>
      <origin rpy="0 0 0" xyz="0 0 0.070"/>
    </collision>
    <inertial>
      <mass value="0.2"/>
      <inertia ixx="0.1" ixy="0.0" ixz="0.0" iyy="0.1" iyz="0.0" izz="0.1"/>
    </inertial>
  </link>
  <joint name="uchopovacL" type="fixed">
    <parent link="model_klb5"/>
    <child link="uchopenie_lavo"/>
    <origin rpy="0 0 1.570795" xyz="0 0 0.02"/>
  </joint>
  <joint name="uchopovacR" type="fixed">
    <parent link="model_klb5"/>
    <child link="uchopenie_pravo"/>
    <origin rpy="0 0 1.570795" xyz="0 0 0.02"/>
  </joint>
  <link name="uchopenie_lavo">
    <visual>
      <geometry>
        <mesh filename="package://pr2_description/meshes/gripper_v0/l_finger.dae"/>
      </geometry>
      <origin rpy="1.570795 -1.570795 0"/>
    </visual>
    <inertial>
      <mass value="0.05"/>
      <inertia ixx="0.1" ixy="0.0" ixz="0.0" iyy="0.1" iyz="0.0" izz="0.1"/>
    </inertial>
  </link>
  <link name="uchopenie_pravo">
    <visual>
      <geometry>
        <mesh filename="package://pr2_description/meshes/gripper_v0/l_finger.dae"/>
      </geometry>
      <origin rpy="1.570795 -1.570795 3.14159"/>
    </visual>
    <inertial>
      <mass value="0.05"/>
      <inertia ixx="0.1" ixy="0.0" ixz="0.0" iyy="0.1" iyz="0.0" izz="0.1"/>
    </inertial>
  </link>
  <transmission name="tran1">
    <type>transmission_interface/SimpleTransmission</type>
    <joint name="klb0">
      <hardwareInterface>EffortJointInterface</hardwareInterface>
    </joint>
    <actuator name="motor1">
      <hardwareInterface>EffortJointInterface</hardwareInterface>
      <mechanicalReduction>3682</mechanicalReduction>
    </actuator>
  </transmission>
  <transmission name="tran2">
    <type>transmission_interface/SimpleTransmission</type>
    <joint name="klb1">
      <hardwareInterface>EffortJointInterface</hardwareInterface>
    </joint>
    <actuator name="motor2">
      <hardwareInterface>EffortJointInterface</hardwareInterface>
      <mechanicalReduction>2547</mechanicalReduction>
    </actuator>
  </transmission>
  <transmission name="tran3">
    <type>transmission_interface/SimpleTransmission</type>
    <joint name="klb2">
      <hardwareInterface>EffortJointInterface</hardwareInterface>
    </joint>
    <actuator name="motor3">
      <hardwareInterface>EffortJointInterface</hardwareInterface>
      <mechanicalReduction>8178</mechanicalReduction>
    </actuator>
  </transmission>
  <transmission name="tran4">
    <type>transmission_interface/SimpleTransmission</type>
    <joint name="klb3">
      <hardwareInterface>EffortJointInterface</hardwareInterface>
    </joint>
    <actuator name="motor4">
      <hardwareInterface>EffortJointInterface</hardwareInterface>
      <mechanicalReduction>6083.64</mechanicalReduction>
    </actuator>
  </transmission>
  <transmission name="tran5">
    <type>transmission_interface/SimpleTransmission</type>
    <joint name="klb4">
      <hardwareInterface>EffortJointInterface</hardwareInterface>
    </joint>
    <actuator name="motor5">
      <hardwareInterface>EffortJointInterface</hardwareInterface>
      <mechanicalReduction>6083.64</mechanicalReduction>
    </actuator>
  </transmission>
  <transmission name="tran6">
    <type>transmission_interface/SimpleTransmission</type>
    <joint name="klb5">
      <hardwareInterface>EffortJointInterface</hardwareInterface>
    </joint>
    <actuator name="motor6">
      <hardwareInterface>EffortJointInterface</hardwareInterface>
      <mechanicalReduction>6083.64</mechanicalReduction>
    </actuator>
  </transmission>
</robot>

