<?xml version="1.0"?>
<robot xmlns:xacro="http://ros.org/wiki/xacro"
       xmlns:xi="http://www.w3.org/2001/XInclude"
       xmlns:gazebo="http://playerstage.sourceforge.net/gazebo/xmlschema/#gz"
       xmlns:model="http://playerstage.sourceforge.net/gazebo/xmlschema/#model"
       xmlns:sensor="http://playerstage.sourceforge.net/gazebo/xmlschema/#sensor"
       xmlns:body="http://playerstage.sourceforge.net/gazebo/xmlschema/#body"
       xmlns:geom="http://playerstage.sourceforge.net/gazebo/xmlschema/#geom"
       xmlns:joint="http://playerstage.sourceforge.net/gazebo/xmlschema/#joint"
       xmlns:interface="http://playerstage.sourceforge.net/gazebo/xmlschema/#interface"
       xmlns:rendering="http://playerstage.sourceforge.net/gazebo/xmlschema/#rendering"
       xmlns:renderable="http://playerstage.sourceforge.net/gazebo/xmlschema/#renderable"
       xmlns:controller="http://playerstage.sourceforge.net/gazebo/xmlschema/#controller"
       xmlns:physics="http://playerstage.sourceforge.net/gazebo/xmlschema/#physics"
       name="kv01" >
  
 <xacro:macro name="kv01_arm" params="parent end_point">
    
    

  <joint name="joint_1" type="revolute">  
  <limit effort="50" lower="-1.75" upper="1.75" velocity="0.2"/>
      <parent link="${parent}"/>
      <child link="model_joint_1"/>
      <origin xyz="0 0 .08" rpy="0 0 0"/>
      <axis xyz="0 0 1"/>
      <dynamika/>
  </joint>

  <link name="model_joint_1">
    <visual>
     <geometry>
       <cylinder radius="0.0725" length="0.258"/>
     </geometry>
     <material name="Blue"/>
     <origin rpy="0 0 0" xyz="0 0 0.08"/>
    </visual>
    <inertial>
       <mass value="0.8"/>
       <inertia_motor/>
       
    </inertial>
  </link>

  <joint name="joint_2" type="revolute">
     <limit effort="100" lower="-1.4" upper="1.4" velocity="0.2"/>
    <parent link="model_joint_1"/>
    <child link="model_joint_2"/>
    <origin xyz="0 0 .258" rpy="${M_PI/2} 0 0"/>
    <axis xyz="0 0 -1"/>
    <dynamika/>
  </joint>

  <link name="model_joint_2">
    <visual>
     <geometry>
       <cylinder radius="0.0725" length="0.180"/>
     </geometry>
     <material name="White"/>
     <origin rpy="0 0 0" xyz="0 0 0"/>
    </visual>
   <collision>
      	<geometry>
       	 <cylinder radius="0.0725" length="0.180"/>
        </geometry>
	 <origin  rpy="0 0 0" xyz="0 0 0"/>
     </collision>
    <inertial>
       <mass value="0.8"/>
       <inertia_motor/>
    </inertial>
   </link>
  
  <joint name="spoj_joint_2_joint_3" type="fixed">
    <parent link="model_joint_2"/>
    <child link="link_1_2"/>
    <origin xyz="0 0.2425 0.028" rpy="-${M_PI/2} 0 0"/>
  </joint>

  <link name="link_1_2">
    <visual>
     <geometry>
       <cylinder radius="0.040" length="0.485"/>
     </geometry>
     <material name="White"/>
     <origin rpy="0 0 0" xyz="0 0 0"/>
    </visual>
    <collision>
      	<geometry>
       	 <cylinder radius="0.070" length="0.330"/>
        </geometry>
	 <origin  rpy="0 0 0" xyz="0 -0.025 0.01"/>
     </collision>
    <inertial>
       <mass value="0.8"/>
       <inertia_zaklad/>
       
    </inertial>
  </link>
  
  <joint name="spoj_joint_2_joint_3_menic" type="fixed">
    <parent link="model_joint_2"/>
    <child link="menic1_2"/>
    <origin xyz="0 0.2425 0.088" rpy="-${M_PI/2} 0 0"/>
  </joint>
    
  <link name="menic1_2">
    <visual>
     <geometry>
       <box size= "0.055 0.050 .285"/>
     </geometry>
     <material name="Blue"/>
     <origin rpy="0 0 0" xyz="0 0 0.010"/>
    </visual>
    <inertial>
       <mass value="0.4"/>
       <inertia_zaklad/>
       
    </inertial>
  </link>

  <joint name="joint_3" type="revolute">
    <limit effort="50" lower="-2.01" upper="2.01" velocity="0.3"/>
    <parent link="model_joint_2"/>
    <child link="model_joint_3"/>
    <origin xyz="0 0.485 0" rpy="0 0 0"/>
    <axis xyz="0 0 1"/>
    <dynamika/>
  </joint>

  <link name="model_joint_3">
    <visual>
     <geometry>
       <cylinder radius="0.045" length="0.190"/>
     </geometry>
     <material name="Blue"/>
     <origin rpy="0 0 0" xyz="0 0 0"/>
    </visual>
    <collision>
      	<geometry>
       	 <cylinder radius="0.050" length="0.195"/>
        </geometry>
	 <origin  rpy="0 0 0" xyz="0 0 0"/>
     </collision>
     <inertial>
       <mass value="0.45"/>
       <inertia_motor/>
       
    </inertial>
  </link>

  <joint name="spoj_joint_3_joint_4" type="fixed">
    <parent link="model_joint_3"/>
    <child link="link_2_3"/>
    <origin xyz="0 0 -0.040" rpy="-${M_PI/2} 0 0"/>
  </joint>

  <link name="link_2_3">
    <visual>
     <geometry>
       <cylinder radius="0.045" length="0.350"/>
     </geometry>
     <material name="Blue"/>
     <origin rpy="0 0 0" xyz="0. 0 0.175"/>
    </visual>
    <collision>
      	<geometry>
       	 <cylinder radius="0.045" length="0.155"/>
        </geometry>
	 <origin  rpy="0 0 0" xyz="0.015 0 0.135"/>
     </collision>
     <inertial>
       <mass value="0.6"/>
       <inertia_zaklad/>
       
    </inertial>
 </link> 
 
 <joint name="joint_4" type="revolute">
    <limit effort="50" velocity="0.2" lower="-3.14" upper="3.14"/>
    <parent link="model_joint_3"/>
    <child link="model_joint_4"/>
    <origin xyz="0 0.350 -0.040 " rpy="-${M_PI/2} 0 0"/>
    <axis xyz="0 0 -1"/>
    <dynamika/>
  </joint>

  <link name="model_joint_4">
    <visual>
     <geometry>
      <box size="0.080 .155 .035"/>
     </geometry>
     <material name="White"/>
     <origin rpy="0 0 0" xyz="0 -0.040  -0.0175"/>
    </visual>
    <collision>
      	<geometry>
       	 <cylinder radius="0.040" length="0.120"/>
        </geometry>
	 <origin  rpy=" 0 0 0" xyz="0 0 -0.055"/>
     </collision>
     <inertial>
       <mass value="0.2"/>
       <inertia_motor/>
       
    </inertial>
  </link>
  
   <joint name="spoj_joint_5_joint_6" type="fixed">
    <parent link="model_joint_4"/>
    <child link="link_3_4"/>
    <origin xyz="0 -0.076 0" rpy="${M_PI} 0 0"/>
  </joint>

  <link name="link_3_4">
    <visual>
     <geometry>
       <cylinder radius="0.027" length="0.2345"/>
     </geometry>
     <material name="White"/>
     <origin rpy="0 0 0" xyz="0 0 0"/>
    </visual>
    <collision>
      	<geometry>
       	 <cylinder radius="0.027" length="0.2335"/>
        </geometry>
	 <origin  rpy="0 0 0" xyz="0 0 0.005"/>
     </collision>
     <inertial>
       <mass value="0.45"/>
       <inertia_zaklad/>
       
    </inertial>
 </link> 
 
   <joint name="spoj_joint_4_joint_5x" type="fixed">
    <parent link="model_joint_4"/>
    <child link="link_3_4x"/>
    <origin xyz="0 -0.052 0.155" rpy="${M_PI/2} 0 0"/>
  </joint>

  <link name="link_3_4x">
    <visual>
     <geometry>
       <cylinder radius="0.040" length="0.145"/>
     </geometry>
     <material name="Blue"/>
     <origin rpy="0 0 0" xyz="0 0 0"/>
    </visual>
    <collision>
      	<geometry>
       	 <cylinder radius="0.040" length="0.145"/>
        </geometry>
	 <origin  rpy="0 0 0" xyz="0 0 0"/>
     </collision>
      <inertial>
       <mass value="0.3"/>
       <inertia_zaklad/>
       
    </inertial>
  </link>
  
  <joint name="joint_5" type="revolute">
    <limit effort="40" lower="-2.09" upper="2.09" velocity="0.2"/>
    <parent link="model_joint_4"/>
    <child link="model_joint_5"/>
    <origin xyz="0 0.036 0.155" rpy="${M_PI/2} 0 0"/>
    <axis xyz="0 0 1"/>
    <dynamika/>
  </joint>

  <link name="model_joint_5">
    <visual>
     <geometry>
        <box size="0.040 0.030 0.080"/>
     </geometry>
     <material name="Blue"/>
     <origin rpy="-${M_PI/2} 0 0" xyz="0 0.025 0"/>
    </visual>
     <collision>
      	<geometry>
       	 <box size="0.040 0.030 0.075"/>
        </geometry>
	 <origin  rpy="-${M_PI/2} 0 0" xyz="0 0 0"/>
     </collision>
     <inertial>
       <mass value="0.08"/>
       <inertia_motor/>
       
    </inertial>
  </link>
  
  <joint name="spoj_menic4_5_gripper" type="fixed">
    <parent link="model_joint_5"/>
    <child link="menic4_5"/>
    <origin xyz="0 0.055 0.015 " rpy="-${M_PI/2} 0 0"/>
  </joint>

  <link name="menic4_5">
    <visual>
     <geometry>
        <box size="0.045 0.110 0.135"/>
     </geometry>
     <material name="Blue"/>
     <origin rpy="0 0 0" xyz="0 0 0.0675"/>
    </visual>
    <collision>
      	<geometry>
       	 <box size="0.045 0.110 0.135"/>
        </geometry>
	 <origin  rpy="0 0 0" xyz="0 0 0.0675"/>
     </collision>
     <inertial>
       <mass value="0.2"/>
       <inertia_zaklad/>
       
    </inertial>
  </link>
  
  <joint name="joint_6" type="revolute">
    <limit effort="40" velocity="0.2" lower="-3.14" upper="3.14"/>
    <parent link="model_joint_5"/>
    <child link="model_joint_6"/>
    <origin xyz = "0 0.190 0.025" rpy="-${M_PI/2}  0 0"/>
    <axis xyz="0 0 -1"/>
    <dynamika/>
  </joint> 
  
  <link name="model_joint_6">
    <visual>
      <geometry>
        <box size="0.01 0.01 0.01"/>
     </geometry>
      <origin xyz = "0 0 0.005" rpy="0 0 0"/>
    </visual>
     <collision>
      	<geometry>
       	 <box size="0.030 0.165 0.135"/>
        </geometry>
	 <origin  rpy="0 0 0" xyz="0 0 0.070"/>
     </collision>
     <inertial>
       <mass value="0.2"/>
       <inertia_zaklad/>
    </inertial>
  </link>
  
 <joint name="uchopovacL" type="fixed">
	<parent link ="model_joint_6"/>
	<child link="uchopenie_lavo"/>
	<origin xyz = "0 0 0.02" rpy="0 0 ${M_PI/2}"/>
	
 </joint>
 <joint name="uchopovacR" type="fixed">
	<parent link ="model_joint_6"/>
	<child link="uchopenie_pravo"/>
	<origin xyz = "0 0 0.02" rpy="0 0 ${M_PI/2}"/>
	
 </joint>
 
  <joint name="centrum_uchopu" type="fixed">
	<parent link ="model_joint_6"/>
	<child link="${end_point}"/>
	<origin xyz = "0 0 0.07" rpy="0 0 0"/>
	
  </joint>


 <link name="uchopenie_lavo">
    <visual>
      <geometry>
        <mesh filename="package://pr2_description/meshes/gripper_v0/l_finger.dae"/>
      </geometry>
	<origin rpy="${M_PI/2} -${M_PI/2} 0"/>
    </visual>
      <inertial>
       <mass value="0.05"/>
       <inertia_zaklad/>
       
    </inertial>
  </link>

 <link name="uchopenie_pravo">
    <visual>
      <geometry>
        <mesh filename="package://pr2_description/meshes/gripper_v0/l_finger.dae"/>
      </geometry>
    <origin rpy="${M_PI/2} -${M_PI/2} ${M_PI}"/>
    </visual>
    <inertial>
       <mass value="0.05"/>
       <inertia_zaklad/>
    </inertial>
  </link>
  
  <link name="${end_point}">
  </link>
  
  <transmission name="tran1">
    <type>transmission_interface/SimpleTransmission</type>
    <joint name="joint_1">
      <hardwareInterface>VelocityJointInterface</hardwareInterface>
      <hardwareInterface>PositionJointInterface</hardwareInterface>
    </joint>
    <actuator name="motor1">
      <hardwareInterface>VelocityJointInterface</hardwareInterface>
      <hardwareInterface>PositionJointInterface</hardwareInterface>
      <mechanicalReduction>3682</mechanicalReduction>
    </actuator>
  </transmission>

  <transmission name="tran2">
    <type>transmission_interface/SimpleTransmission</type>
    <joint name="joint_2">
      <hardwareInterface>VelocityJointInterface</hardwareInterface>
      <hardwareInterface>PositionJointInterface</hardwareInterface>
    </joint>
    <actuator name="motor2">
      <hardwareInterface>VelocityJointInterface</hardwareInterface>
      <hardwareInterface>PositionJointInterface</hardwareInterface>
      <mechanicalReduction>2547</mechanicalReduction>
    </actuator>
    </transmission>

   <transmission name="tran3">
    <type>transmission_interface/SimpleTransmission</type>
    <joint name="joint_3">
      <hardwareInterface>VelocityJointInterface</hardwareInterface>
      <hardwareInterface>PositionJointInterface</hardwareInterface>
    </joint>
    <actuator name="motor3">
      <hardwareInterface>VelocityJointInterface</hardwareInterface>
      <hardwareInterface>PositionJointInterface</hardwareInterface>
      <mechanicalReduction>8178</mechanicalReduction>
    </actuator>
   </transmission>


   <transmission name="tran4">
    <type>transmission_interface/SimpleTransmission</type>
    <joint name="joint_4">
      <hardwareInterface>VelocityJointInterface</hardwareInterface>
      <hardwareInterface>PositionJointInterface</hardwareInterface>
    </joint>
    
    <actuator name="motor4">
      <hardwareInterface>VelocityJointInterface</hardwareInterface>
      <hardwareInterface>PositionJointInterface</hardwareInterface>
      <mechanicalReduction>6083.64</mechanicalReduction>
    </actuator>
   </transmission>

  <transmission name="tran5">
    <type>transmission_interface/SimpleTransmission</type>
    <joint name="joint_5">
      <hardwareInterface>VelocityJointInterface</hardwareInterface>
      <hardwareInterface>PositionJointInterface</hardwareInterface>
    </joint>
    <actuator name="motor5">
      <hardwareInterface>VelocityJointInterface</hardwareInterface>
      <hardwareInterface>PositionJointInterface</hardwareInterface>
      <mechanicalReduction>6083.64</mechanicalReduction>
    </actuator>
  </transmission>

  <transmission name="tran6">
    <type>transmission_interface/SimpleTransmission</type>
    <joint name="joint_6">
      <hardwareInterface>VelocityJointInterface</hardwareInterface>
      <hardwareInterface>PositionJointInterface</hardwareInterface>
    </joint>
    <actuator name="motor6">
      <hardwareInterface>VelocityJointInterface</hardwareInterface>
      <hardwareInterface>PositionJointInterface</hardwareInterface>
      <mechanicalReduction>6083.64</mechanicalReduction>
    </actuator>
  </transmission>
    
 </xacro:macro>

</robot>

